<FEEDBACK>
The code was tested on multiple trials with valid inputs but encountered the following error:
Traceback (most recent call last):
  File "C:\Users\User\Documents\Code\LLM-IK\llm_ik.py", line 2607, in run_code
    joints = func_timeout(MAX_TIME, self.code[lower][upper][solving][mode], args=[position])
             ^^^^^^^^^^^^^^^^^^^^^^^^^^^^^^^^^^^^^^^^^^^^^^^^^^^^^^^^^^^^^^^^^^^^^^^^^^^^^^^
  File "C:\Users\User\Documents\Code\LLM-IK\.venv\Lib\site-packages\func_timeout\dafunc.py", line 108, in func_timeout
    raise_exception(exception)
  File "C:\Users\User\Documents\Code\LLM-IK\.venv\Lib\site-packages\func_timeout\py3_raise.py", line 7, in raise_exception
    raise exception[0] from None
  File "C:\Users\User\Documents\Code\LLM-IK\Solutions\UR5\OpenAI GPT-4o\1-3-Position-Dynamic.py", line 17, in inverse_kinematics
    theta2 = math.atan2(y_target_adjusted - l1, r) - math.acos((l1 ** 2 + d ** 2 - l2 ** 2) / (2 * l1 * d))
                                                     ^^^^^^^^^^^^^^^^^^^^^^^^^^^^^^^^^^^^^^^^^^^^^^^^^^^^^^
ValueError: math domain error

</FEEDBACK>