<FEEDBACK>
The code was tested on multiple trials with valid inputs but encountered the following error:
Traceback (most recent call last):
  File "C:\Users\User\Documents\Code\LLM-IK\llm_ik.py", line 2607, in run_code
    joints = func_timeout(MAX_TIME, self.code[lower][upper][solving][mode], args=[position])
             ^^^^^^^^^^^^^^^^^^^^^^^^^^^^^^^^^^^^^^^^^^^^^^^^^^^^^^^^^^^^^^^^^^^^^^^^^^^^^^^
  File "C:\Users\User\Documents\Code\LLM-IK\.venv\Lib\site-packages\func_timeout\dafunc.py", line 108, in func_timeout
    raise_exception(exception)
  File "C:\Users\User\Documents\Code\LLM-IK\.venv\Lib\site-packages\func_timeout\py3_raise.py", line 7, in raise_exception
    raise exception[0] from None
  File "C:\Users\User\Documents\Code\LLM-IK\Solutions\UR5\OpenAI GPT-4o\4-5-Position-Dynamic.py", line 15, in inverse_kinematics
    theta2 = math.atan2(d, r) - math.atan2(L2, math.sqrt(r ** 2 + d ** 2 - L2 ** 2))
                                               ^^^^^^^^^^^^^^^^^^^^^^^^^^^^^^^^^^^^
ValueError: math domain error

</FEEDBACK>