<FEEDBACK>
The code was tested on multiple trials with valid inputs but encountered the following error:
Traceback (most recent call last):
  File "C:\Users\User\Documents\Code\LLM-IK\llm_ik.py", line 2607, in run_code
    joints = func_timeout(MAX_TIME, self.code[lower][upper][solving][mode], args=[position])
             ^^^^^^^^^^^^^^^^^^^^^^^^^^^^^^^^^^^^^^^^^^^^^^^^^^^^^^^^^^^^^^^^^^^^^^^^^^^^^^^
  File "C:\Users\User\Documents\Code\LLM-IK\.venv\Lib\site-packages\func_timeout\dafunc.py", line 108, in func_timeout
    raise_exception(exception)
  File "C:\Users\User\Documents\Code\LLM-IK\.venv\Lib\site-packages\func_timeout\py3_raise.py", line 7, in raise_exception
    raise exception[0] from None
  File "C:\Users\User\Documents\Code\LLM-IK\Solutions\UR5\OpenAI GPT-4o\1-4-Position-Extend.py", line 18, in inverse_kinematics
    sin_theta2 = math.sqrt(1 - cos_theta2 ** 2)
                 ^^^^^^^^^^^^^^^^^^^^^^^^^^^^^^
ValueError: math domain error

</FEEDBACK>