<FEEDBACK>
The code was tested on multiple trials with valid inputs but encountered the following errors:
Traceback (most recent call last):
  File "C:\Users\User\Documents\Code\LLM-IK\llm_ik.py", line 2502, in run_code
    joints = func_timeout(MAX_TIME, self.code[lower][upper][solving][mode], args=[position])
             ^^^^^^^^^^^^^^^^^^^^^^^^^^^^^^^^^^^^^^^^^^^^^^^^^^^^^^^^^^^^^^^^^^^^^^^^^^^^^^^
  File "C:\Users\User\Documents\Code\LLM-IK\.venv\Lib\site-packages\func_timeout\dafunc.py", line 108, in func_timeout
    raise_exception(exception)
  File "C:\Users\User\Documents\Code\LLM-IK\.venv\Lib\site-packages\func_timeout\py3_raise.py", line 7, in raise_exception
    raise exception[0] from None
  File "C:\Users\User\Documents\Code\LLM-IK\Solutions\UR5\DeepSeek R1\1-5-Position-Dynamic.py", line 5, in inverse_kinematics
    theta1, theta2 = inverse_kinematics_existing1((x_target, 0, z_target))
                     ^^^^^^^^^^^^^^^^^^^^^^^^^^^^^^^^^^^^^^^^^^^^^^^^^^^^^
  File "C:\Users\User\Documents\Code\LLM-IK\Solutions\UR5\DeepSeek R1\1-5-Position-Dynamic.py", line 27, in inverse_kinematics_existing1
    theta2 = math.acos(cos_theta2)
             ^^^^^^^^^^^^^^^^^^^^^
ValueError: math domain error

Traceback (most recent call last):
  File "C:\Users\User\Documents\Code\LLM-IK\llm_ik.py", line 2502, in run_code
    joints = func_timeout(MAX_TIME, self.code[lower][upper][solving][mode], args=[position])
             ^^^^^^^^^^^^^^^^^^^^^^^^^^^^^^^^^^^^^^^^^^^^^^^^^^^^^^^^^^^^^^^^^^^^^^^^^^^^^^^
  File "C:\Users\User\Documents\Code\LLM-IK\.venv\Lib\site-packages\func_timeout\dafunc.py", line 108, in func_timeout
    raise_exception(exception)
  File "C:\Users\User\Documents\Code\LLM-IK\.venv\Lib\site-packages\func_timeout\py3_raise.py", line 7, in raise_exception
    raise exception[0] from None
  File "C:\Users\User\Documents\Code\LLM-IK\Solutions\UR5\DeepSeek R1\1-5-Position-Dynamic.py", line 18, in inverse_kinematics
    theta3, theta4, theta5 = inverse_kinematics_existing2((dx_local, dy_local, dz_local))
                             ^^^^^^^^^^^^^^^^^^^^^^^^^^^^^^^^^^^^^^^^^^^^^^^^^^^^^^^^^^^^
  File "C:\Users\User\Documents\Code\LLM-IK\Solutions\UR5\DeepSeek R1\1-5-Position-Dynamic.py", line 67, in inverse_kinematics_existing2
    raise ValueError('Target position is unreachable')
ValueError: Target position is unreachable

</FEEDBACK>