<FEEDBACK>
The code was tested on multiple trials with valid inputs but encountered the following error:
Traceback (most recent call last):
  File "C:\Users\User\Documents\Code\LLM-IK\llm_ik.py", line 2592, in run_code
    joints = self.code[lower][upper][solving][mode](position)
             ^^^^^^^^^^^^^^^^^^^^^^^^^^^^^^^^^^^^^^^^^^^^^^^^
  File "C:\Users\User\Documents\Code\LLM-IK\Solutions\UR5\OpenAI GPT-4o\0-2-Position-Cumulative.py", line 15, in inverse_kinematics
    raise ValueError('Target position is out of reach.')
ValueError: Target position is out of reach.

</FEEDBACK>